<?xml version="1.0"?>
<robot name="alfred">
  <link name="base">
    <visual>
      <geometry>
        <box size="0.27 .25 .065"/>
      </geometry>
      <origin xyz="0 0 0.0325"/>
      <material name="orange">
        <color rgba="0.9 0.27 0.0 1"/> <!-- 0.54 -->
      </material>
    </visual>
    <collision>
      <geometry>
        <box size="0.27 .25 .065"/>
      </geometry>
    </collision>
  </link>

  <link name="cylinder">
    <visual>
      <geometry>
        <cylinder length="0.035" radius="0.085"/>
      </geometry>
      <origin xyz="0 0 0.0175"/>
      <material name="orange"/>
    </visual>
    <collision>
      <geometry>
        <cylinder length="0.035" radius="0.085"/>
      </geometry>
    </collision>
  </link>

  <link name="base_s6">
    <visual>
      <geometry>
        <box size="0.06 .04 .035"/>
      </geometry>
      <origin xyz="-0.015 0 0.0175"/>
      <material name="orange"/>
    </visual>
    <collision>
      <geometry>
        <box size="0.06 .04 .035"/>
      </geometry>
    </collision>
  </link>

  <link name="shoulder_s5">
    <visual>
      <geometry>
        <box size="0.025 .06 .105"/>
      </geometry>
      <origin xyz="0 0 0.0395"/>
      <material name="orange"/>
    </visual>
    <collision>
      <geometry>
        <box size="0.025 .06 .105"/>
      </geometry>
    </collision>
  </link>

  <link name="elbow_s4">
    <visual>
      <geometry>
        <box size="0.03 .04 .12"/>
      </geometry>
      <origin xyz="0 0 0.040"/>
      <material name="orange"/>
    </visual>
    <collision>
      <geometry>
        <box size="0.03 .04 .12"/>
      </geometry>
    </collision>
  </link>

  <link name="wrist_s3">
    <visual>
      <geometry>
        <box size="0.025 .06 .07"/>
      </geometry>
      <origin xyz="0 0 0.025"/>
      <material name="orange"/>
    </visual>
    <collision>
      <geometry>
        <box size="0.025 .06 .07"/>
      </geometry>
    </collision>
  </link>

  <link name="wrist_s2">
    <visual>
      <geometry>
        <box size="0.017 .05 .075"/>
      </geometry>
      <origin xyz="0 0 0.0375"/>
      <material name="orange"/>
    </visual>
    <collision>
      <geometry>
        <box size="0.017 .05 .075"/>
      </geometry>
    </collision>
  </link>

  <link name="wrist_box_s2">
    <visual>
      <geometry>
        <box size="0.04 .05 .035"/>
      </geometry>
      <origin xyz="0.02 0 0.0175"/>
      <material name="orange"/>
    </visual>
    <collision>
      <geometry>
        <box size="0.04 .05 .035"/>
      </geometry>
    </collision>
  </link>

  <link name="camera">
    <visual>
      <geometry>
        <box size="0.025 .04 .035"/>
      </geometry>
      <origin xyz="0.0125 0 0.0175"/>
      <material name="black"/>
    </visual>
    <collision>
      <geometry>
        <box size="0.025 .04 .035"/>
      </geometry>
    </collision>
  </link>

  <link name="gripper_left">
    <visual>
      <geometry>
        <box size="0.01 .02 .05"/>
      </geometry>
      <origin xyz="0 0 0.025"/>
      <material name="orange"/>
    </visual>
    <collision>
      <geometry>
        <box size="0.01 .02 .05"/>
      </geometry>
    </collision>
  </link>

  <link name="gripper_right">
    <visual>
      <geometry>
        <box size="0.01 .02 .05"/>
      </geometry>
      <origin xyz="0 0 0.025"/>
      <material name="orange"/>
    </visual>
    <collision>
      <geometry>
        <box size="0.01 .02 .05"/>
      </geometry>
    </collision>
  </link>

  <joint name="box_to_cylinder" type="fixed">
    <parent link="base"/>
    <child link="cylinder"/>
    <origin xyz="0 0 0.06"/>
  </joint>

  <joint name="servo_6" type="revolute">
    <parent link="cylinder"/>
    <child link="base_s6"/>
    <axis xyz="0 0 1"/>
    <limit effort="1000.0" lower="-1.7453292519943" upper="1.7453292519943" velocity="0.9"/>
    <origin xyz="0 0 0.055"/>
  </joint>

  <joint name="servo_5" type="revolute">
    <parent link="base_s6"/>
    <child link="shoulder_s5"/>
    <limit effort="1000.0" lower="-1.7453292519943" upper="1.7453292519943" velocity="0.9"/>
    <axis xyz="0 1 0"/>
    <origin xyz="0 0 0.015"/>
  </joint>

  <joint name="servo_4" type="revolute">
    <parent link="shoulder_s5"/>
    <child link="elbow_s4"/>
    <limit effort="1000.0" lower="-1.7453292519943" upper="1.7453292519943" velocity="0.9"/>
    <axis xyz="0 -1 0"/>
    <origin xyz="0 0 0.08"/>
  </joint>

  <joint name="servo_3" type="revolute">
    <parent link="elbow_s4"/>
    <child link="wrist_s3"/>
    <limit effort="1.0" lower="-1.7453292519943" upper="1.7453292519943" velocity="0.9"/>
    <axis xyz="0 1 0"/>
    <origin xyz="0 0 0.08"/>
  </joint>

  <joint name="servo_2" type="revolute">
    <parent link="wrist_s3"/>
    <child link="wrist_s2"/>
    <limit effort="1000.0" lower="-3.1415926535898" upper="0.0" velocity="0.9"/>    
    <axis xyz="0 0 1"/>
    <origin xyz="0 0 0.065" rpy="0 0 -3.1415926535898"/>
  </joint>

  <joint name="wrist_s2_to_wrist_box_s2" type="fixed">
    <parent link="wrist_s2"/>
    <child link="wrist_box_s2"/>
    <origin xyz="0.0085 0 0"/>
  </joint>

  <joint name="_wrist_box_s2_to_camera" type="fixed">
    <parent link="wrist_box_s2"/>
    <child link="camera"/>
    <origin xyz="0.04 0 0.04" rpy="0 -0.34906585039887 0"/>
  </joint>

  <joint name="gripper_finger_left" type="prismatic">
    <parent link="wrist_s2"/>
    <child link="gripper_left"/>
    <axis xyz="0 1 0"/>
    <limit effort="1000.0" lower="0" upper="0.015" velocity="0.9"/>
    <origin xyz="0 -0.025 .075"/>
  </joint>

  <joint name="gripper_finger_right" type="prismatic">
    <parent link="wrist_s2"/>
    <child link="gripper_right"/>
    <axis xyz="0 1 0"/>
    <limit effort="1000.0" lower="-0.015" upper="0" velocity="0.9"/>
    <origin xyz="0 0.025 .075"/>
  </joint>
</robot>
